Workbook

Sheet README
B2: Data Catalogs
B5: # | C5: Name | D5: Table | E5: Total
B6: 1 | C6: Language Families | D6: lang_families | E6: =COUNT(lang_families[id]) -> 118
B7: 2 | C7: Language Scopes | D7: lang_scopes | E7: =COUNT(lang_scopes[id]) -> 3
B8: 3 | C8: Language Scripts | D8: lang_scripts | E8: =COUNT(lang_scripts[id]) -> 29
B9: 4 | C9: Language Types | D9: lang_types | E9: =COUNT(lang_types[id]) -> 6
B10: 5 | C10: Languages | D10: languages | E10: =COUNT(languages[id]) -> 183
B11: 6 | C11: Locales | D11: locales | E11: =COUNT(locales[id]) -> 413
B14: =IF(C14="Facebook",HYPERLINK("https://facebook.com/dyntarafamily","ⓕ"),IF(C14="Twitter/X",HYPERLINK("https://x.com/dyntarafamily","𝕏"),IF(C14="Instagram",HYPERLINK("https://instagram.com/dyntarafamily","🧿"),IF(C14="LinkedIn",HYPERLINK("https://linkedin.com/in/dyo-wiranata-mulya","[in]"),IF(C14="YouTube",HYPERLINK("https://www.youtube.com/@DyoWiranataMulya","▶️"),IF(C14="GitHub",HYPERLINK("https://github.com/dyonmulya","🐱"),"")))))) -> ⓕ | C14: Facebook | D14: =HYPERLINK("","📜 MIT License") -> 📜 MIT License
B16: ="Copyright © "&IF(YEAR(NOW())=2025,"2025","2025-"&YEAR(NOW()))&" "&HYPERLINK("https://github.com/dyonmulya","Dyo Wiranata Mulya") -> Copyright © 2025 Dyo Wiranata Mulya

Sheet lang_families
A1: id | B1: parent_id | C1: iso_639_5 | D1: name
A2: 1 | C2: aav | D2: Austro-Asiatic languages
A3: 2 | C3: afa | D3: Afro-Asiatic languages
A4: 3 | C4: art | D4: Artificial languages
A5: 4 | C5: aus | D5: Australian languages
A6: 5 | C6: cai | D6: Central American Indian languages
A7: 6 | C7: cau | D7: Caucasian languages
A8: 7 | C8: crp | D8: creoles and pidgins
A9: 8 | C9: day | D9: Land Dayak languages
A10: 9 | C10: dra | D10: Dravidian languages
A11: 10 | C11: esx | D11: Eskimo-Aleut languages
A12: 11 | C12: euq | D12: Basque (family)
A13: 12 | C13: hmx | D13: Hmong-Mien languages
... A30: 29 | C30: kor | D30: Koreanic
A31: 30 | B31: =A19 -> 18 | C31: alv | D31: Atlantic-Congo languages
A32: 31 | B32: =A21 -> 20 | C32: aqa | D32: Alacalufan languages
A33: 32 | B33: =A18 -> 17 | C33: aql | D33: Algic languages
A34: 33 | B34: =A21 -> 20 | C34: awd | D34: Arawakan languages
A35: 34 | B35: =A18 -> 17 | C35: azc | D35: Uto-Aztecan languages
A36: 35 | B36: =A14 -> 13 | C36: bat | D36: Baltic languages
A37: 36 | B37: =A3 -> 2 | C37: ber | D37: Berber languages
A38: 37 | B38: =A21 -> 20 | C38: cba | D38: Chibchan languages
A39: 38 | B39: =A7 -> 6 | C39: ccn | D39: North Caucasian languages
A40: 39 | B40: =A7 -> 6 | C40: ccs | D40: South Caucasian languages
A41: 40 | B41: =A3 -> 2 | C41: cdc | D41: Chadic languages
A42: 41 | B42: =A18 -> 17 | C42: cdd | D42: Caddoan languages
A43: 42 | B43: =A14 -> 13 | C43: cel | D43: Celtic languages
A44: 43 | B44: =A8 -> 7 | C44: cpe | D44: creoles and pidgins, English-based
A45: 44 | B45: =A8 -> 7 | C45: cpf | D45: creoles and pidgins, French-based
A46: 45 | B46: =A8 -> 7 | C46: cpp | D46: creoles and pidgins, Portuguese-based
A47: 46 | B47: =A24 -> 23 | C47: csu | D47: Central Sudanic languages
A48: 47 | B48: =A3 -> 2 | C48: cus | D48: Cushitic languages
A49: 48 | B49: =A19 -> 18 | C49: dmn | D49: Mande languages
A50: 49 | B50: =A3 -> 2 | C50: egx | D50: Egyptian languages
A51: 50 | B51: =A27 -> 26 | C51: fiu | D51: Finno-Ugrian languages
A52: 51 | B52: =A17 -> 16 | C52: fox | D52: Formosan languages
A53: 52 | B53: =A14 -> 13 | C53: gem | D53: Germanic languages
A54: 53 | B54: =A14 -> 13 | C54: grk | D54: Greek languages
A55: 54 | B55: =A18 -> 17 | C55: hok | D55: Hokan languages
A56: 55 | B56: =A14 -> 13 | C56: hyx | D56: Armenian (family)
...

Sheet lang_scopes
A1: id | B1: name | C1: description
A2: 1 | B2: individual language | C2: Normal, single language.
A3: 2 | B3: macrolanguage | C3: One-to-many grouping of languages, because older ISO 639s included them.
A4: 3 | B4: special code | C4: Non-language codes.
A5: Total | C5: =SUBTOTAL(103,lang_scopes[id]) -> 3

Sheet lang_scripts
A1: id | B1: iso_15924_code | C1: iso_15924_numeric | D1: name | E1: direction
A2: 1 | B2: Latn | C2: 215 | D2: Latin | E2: ltr
A3: 2 | B3: Cyrl | C3: 220 | D3: Cyrillic | E3: ltr
A4: 3 | B4: Ethi | C4: 430 | D4: Ethiopic (Ge_ez) | E4: ltr
A5: 4 | B5: Arab | C5: 160 | D5: Arabic | E5: rtl
A6: 5 | B6: Beng | C6: 325 | D6: Bengali | E6: ltr
A7: 6 | B7: Tibt | C7: 330 | D7: Tibetan | E7: ltr
A8: 7 | B8: Cans | C8: 440 | D8: Unified Canadian Aboriginal Syllabics | E8: ltr
A9: 8 | B9: Thaa | C9: 170 | D9: Thaana | E9: rtl
A10: 9 | B10: Grek | C10: 200 | D10: Greek | E10: ltr
A11: 10 | B11: Gujr | C11: 320 | D11: Gujarati | E11: ltr
A12: 11 | B12: Hebr | C12: 125 | D12: Hebrew | E12: rtl
A13: 12 | B13: Deva | C13: 315 | D13: Devanagari (Nagari) | E13: ltr
... A30: 29 | B30: Hans | C30: 501 | D30: Han (Simplified variant) | E30: ltr
A31: Total | E31: =SUBTOTAL(103,lang_scripts[id]) -> 29

Sheet lang_types
A1: id | B1: name | C1: description
A2: 1 | B2: living | C2: A language that is still being used and spoken by people.
A3: 2 | B3: ancient | C3: Any language originating in times that may be referred to as ancient.
A4: 3 | B4: constructed | C4: A language whose phonology, grammar, and vocabulary, instead of having developed naturally, are consciously devised for some purpose, which may include being devised for a work of fiction.
A5: 4 | B5: extinct | C5: A language that no longer is the first language or the second language of anyone.
A6: 5 | B6: historical | C6: Languages that were spoken in a historical period, but that are distinct from their modern form
A7: 6 | B7: special code | C7: These language codes should generally be canonical language tags as defined by BCP 47.
A8: Total | C8: =SUBTOTAL(103,lang_types[description]) -> 6

Sheet languages
A1: id | B1: iso_639_1 | C1: iso_639_2 | D1: iso_639_3 | E1: family_id | F1: scope_id | G1: script_id | H1: type_id | I1: aname | J1: uname | K1: flag
A2: 1 | B2: aa | C2: aar | D2: aar | E2: =lang_families!A3 -> 2 | F2: =lang_scopes!A2 -> 1 | G2: =lang_scripts!A2 -> 1 | H2: =lang_types!A2 -> 1 | I2: Afar | J2: Afaraf | K2: https://raw.githubusercontent.com/dyonmulya/resources/refs/heads/main/assets/images/b2d3a12dc55a7ed8714197cb3de15e03.svg
A3: 2 | B3: ab | C3: abk | D3: abk | E3: =lang_families!A39 -> 38 | F3: =lang_scopes!A2 -> 1 | G3: =lang_scripts!A3 -> 2 | H3: =lang_types!A2 -> 1 | I3: Abkhazian | J3: Аԥсуа бызшәа | K3: https://raw.githubusercontent.com/dyonmulya/resources/refs/heads/main/assets/images/1999fcc40084fd7ec220ed474a05f831.svg
A4: 3 | B4: ae | C4: ave | D4: ave | E4: =lang_families!A14 -> 13 | F4: =lang_scopes!A2 -> 1 | G4: =lang_scripts!A2 -> 1 | H4: =lang_types!A3 -> 2 | I4: Avestan | J4: avesta | K4: https://raw.githubusercontent.com/dyonmulya/resources/refs/heads/main/assets/images/1c30626fbed238af50de75095434d7af.svg
A5: 4 | B5: af | C5: afr | D5: afr | E5: =lang_families!A14 -> 13 | F5: =lang_scopes!A2 -> 1 | G5: =lang_scripts!A2 -> 1 | H5: =lang_types!A2 -> 1 | I5: Afrikaans | J5: Afrikaans | K5: https://raw.githubusercontent.com/dyonmulya/resources/refs/heads/main/assets/images/b83474968d560ae0f443105470df5e36.svg
A6: 5 | B6: ak | C6: aka | D6: aka | E6: =lang_families!A19 -> 18 | F6: =lang_scopes!A3 -> 2 | G6: =lang_scripts!A2 -> 1 | H6: =lang_types!A2 -> 1 | I6: Akan | J6: Akan | K6: https://raw.githubusercontent.com/dyonmulya/resources/refs/heads/main/assets/images/01ecc1e8d644e31d9fc33552ee7f449c.svg
A7: 6 | B7: am | C7: amh | D7: amh | E7: =lang_families!A3 -> 2 | F7: =lang_scopes!A2 -> 1 | G7: =lang_scripts!A4 -> 3 | H7: =lang_types!A2 -> 1 | I7: Amharic | J7: አማርኛ | K7: https://raw.githubusercontent.com/dyonmulya/resources/refs/heads/main/assets/images/6f4fda0d1e8f4ba04e6619d26acba6eb.svg
A8: 7 | B8: an | C8: arg | D8: arg | E8: =lang_families!A14 -> 13 | F8: =lang_scopes!A2 -> 1 | G8: =lang_scripts!A2 -> 1 | H8: =lang_types!A2 -> 1 | I8: Aragonese | J8: aragons | K8: https://raw.githubusercontent.com/dyonmulya/resources/refs/heads/main/assets/images/1607580d66a151a4b9edb5301fe778fb.svg
A9: 8 | B9: ar | C9: ara | D9: ara | E9: =lang_families!A3 -> 2 | F9: =lang_scopes!A3 -> 2 | G9: =lang_scripts!A5 -> 4 | H9: =lang_types!A2 -> 1 | I9: Arabic | J9: العربية | K9: https://raw.githubusercontent.com/dyonmulya/resources/refs/heads/main/assets/images/a140c5e5af3e9fc696366588536b424e.svg
A10: 9 | B10: as | C10: asm | D10: asm | E10: =lang_families!A14 -> 13 | F10: =lang_scopes!A2 -> 1 | G10: =lang_scripts!A6 -> 5 | H10: =lang_types!A2 -> 1 | I10: Assamese | J10: অসমীয়া | K10: https://raw.githubusercontent.com/dyonmulya/resources/refs/heads/main/assets/images/4e39a2bfe2c716c9453d5a7aee9b7dac.svg
A11: 10 | B11: av | C11: ava | D11: ava | E11: =lang_families!A39 -> 38 | F11: =lang_scopes!A2 -> 1 | G11: =lang_scripts!A3 -> 2 | H11: =lang_types!A2 -> 1 | I11: Avaric | J11: авар мацӀ | K11: https://raw.githubusercontent.com/dyonmulya/resources/refs/heads/main/assets/images/f47b3c715590ca86667c549087d3658e.svg
A12: 11 | B12: ay | C12: aym | D12: aym | E12: =lang_families!A28 -> 27 | F12: =lang_scopes!A3 -> 2 | G12: =lang_scripts!A2 -> 1 | H12: =lang_types!A2 -> 1 | I12: Aymara | J12: aymar aru | K12: https://raw.githubusercontent.com/dyonmulya/resources/refs/heads/main/assets/images/75da65326764ad91e67c80d4c02fd705.svg
A13: 12 | B13: az | C13: aze | D13: aze | E13: =lang_families!A78 -> 77 | F13: =lang_scopes!A3 -> 2 | G13: =lang_scripts!A2 -> 1 | H13: =lang_types!A2 -> 1 | I13: Azerbaijani | J13: azərbaycanca | K13: https://raw.githubusercontent.com/dyonmulya/resources/refs/heads/main/assets/images/e13cf2c8784638a1ff1b44127a11c88d.svg
A14: 13 | B14: ba | C14: bak | D14: bak | E14: =lang_families!A78 -> 77 | F14: =lang_scopes!A2 -> 1 | G14: =lang_scripts!A3 -> 2 | H14: =lang_types!A2 -> 1 | I14: Bashkir | J14: башҡорт теле | K14: https://raw.githubusercontent.com/dyonmulya/resources/refs/heads/main/assets/images/55c66dfc3ef5e46fbf1020ac75ababf6.svg
A15: 14 | B15: be | C15: bel | D15: bel | E15: =lang_families!A14 -> 13 | F15: =lang_scopes!A2 -> 1 | G15: =lang_scripts!A3 -> 2 | H15: =lang_types!A2 -> 1 | I15: Belarusian | J15: беларуская | K15: https://raw.githubusercontent.com/dyonmulya/resources/refs/heads/main/assets/images/f2acc981a5e03b08a12c395a43a67194.svg
A16: 15 | B16: bg | C16: bul | D16: bul | E16: =lang_families!A14 -> 13 | F16: =lang_scopes!A2 -> 1 | G16: =lang_scripts!A3 -> 2 | H16: =lang_types!A2 -> 1 | I16: Bulgarian | J16: български | K16: https://raw.githubusercontent.com/dyonmulya/resources/refs/heads/main/assets/images/971dc0a0b8d6bbfcd57014d9396dc13d.svg
A17: 16 | B17: bi | C17: bis | D17: bis | E17: =lang_families!A44 -> 43 | F17: =lang_scopes!A2 -> 1 | G17: =lang_scripts!A2 -> 1 | H17: =lang_types!A2 -> 1 | I17: Bislama | J17: Bislama | K17: https://raw.githubusercontent.com/dyonmulya/resources/refs/heads/main/assets/images/2962d376b7631069c57f6adea15f0ca9.svg
A18: 17 | B18: bm | C18: bam | D18: bam | E18: =lang_families!A19 -> 18 | F18: =lang_scopes!A2 -> 1 | G18: =lang_scripts!A2 -> 1 | H18: =lang_types!A2 -> 1 | I18: Bambara | J18: bamanankan | K18: https://raw.githubusercontent.com/dyonmulya/resources/refs/heads/main/assets/images/3a2788de37bf4efb90a4751f01255efb.svg
A19: 18 | B19: bn | C19: ben | D19: ben | E19: =lang_families!A14 -> 13 | F19: =lang_scopes!A2 -> 1 | G19: =lang_scripts!A6 -> 5 | H19: =lang_types!A2 -> 1 | I19: Bangla | J19: বাংলা | K19: https://raw.githubusercontent.com/dyonmulya/resources/refs/heads/main/assets/images/c7eab98d8d1e9a13348f4df40809cd2a.svg
A20: 19 | B20: bo | C20: bod | D20: bod | E20: =lang_families!A23 -> 22 | F20: =lang_scopes!A2 -> 1 | G20: =lang_scripts!A7 -> 6 | H20: =lang_types!A2 -> 1 | I20: Tibetan | J20: པོད་སྐད་ | K20: https://raw.githubusercontent.com/dyonmulya/resources/refs/heads/main/assets/images/8055e4976b296bcef6591b7aa38873dc.svg
A21: 20 | B21: br | C21: bre | D21: bre | E21: =lang_families!A14 -> 13 | F21: =lang_scopes!A2 -> 1 | G21: =lang_scripts!A2 -> 1 | H21: =lang_types!A2 -> 1 | I21: Breton | J21: brezhoneg | K21: https://raw.githubusercontent.com/dyonmulya/resources/refs/heads/main/assets/images/4c3ace878f8013a7ba6ee677018120fc.svg
A22: 21 | B22: bs | C22: bos | D22: bos | E22: =lang_families!A14 -> 13 | F22: =lang_scopes!A2 -> 1 | G22: =lang_scripts!A2 -> 1 | H22: =lang_types!A2 -> 1 | I22: Bosnian | J22: bosanski | K22: https://raw.githubusercontent.com/dyonmulya/resources/refs/heads/main/assets/images/f91e2d7da6b43be6fe77e8306ea2aab6.svg
A23: 22 | B23: ca | C23: cat | D23: cat | E23: =lang_families!A14 -> 13 | F23: =lang_scopes!A2 -> 1 | G23: =lang_scripts!A2 -> 1 | H23: =lang_types!A2 -> 1 | I23: Catalan | J23: català | K23: https://raw.githubusercontent.com/dyonmulya/resources/refs/heads/main/assets/images/3d3c678e041add04e84d24854734110d.svg
A24: 23 | B24: ce | C24: che | D24: che | E24: =lang_families!A39 -> 38 | F24: =lang_scopes!A2 -> 1 | G24: =lang_scripts!A3 -> 2 | H24: =lang_types!A2 -> 1 | I24: Chechen | J24: нохчийн мотт | K24: https://raw.githubusercontent.com/dyonmulya/resources/refs/heads/main/assets/images/e966a53fa47da0c3c90e245f3c6704ab.svg
A25: 24 | B25: ch | C25: cha | D25: cha | E25: =lang_families!A17 -> 16 | F25: =lang_scopes!A2 -> 1 | G25: =lang_scripts!A2 -> 1 | H25: =lang_types!A2 -> 1 | I25: Chamorro | J25: Chamoru | K25: https://raw.githubusercontent.com/dyonmulya/resources/refs/heads/main/assets/images/1f3b40feeb36bdb0e7abb94e90f5e348.svg
A26: 25 | B26: co | C26: cos | D26: cos | E26: =lang_families!A14 -> 13 | F26: =lang_scopes!A2 -> 1 | G26: =lang_scripts!A2 -> 1 | H26: =lang_types!A2 -> 1 | I26: Corsican | J26: corsu, lingua corsa | K26: https://raw.githubusercontent.com/dyonmulya/resources/refs/heads/main/assets/images/0d1cda06672808f3b06990f9e87f3ed9.svg
A27: 26 | B27: cr | C27: cre | D27: cre | E27: =lang_families!A33 -> 32 | F27: =lang_scopes!A3 -> 2 | G27: =lang_scripts!A8 -> 7 | H27: =lang_types!A2 -> 1 | I27: Cree | J27: ᓀᐦᐃᔭᐍᐏᐣ | K27: https://raw.githubusercontent.com/dyonmulya/resources/refs/heads/main/assets/images/04704a1907094b6e2860b00bcace7b8e.svg
A28: 27 | B28: cs | C28: ces | D28: ces | E28: =lang_families!A14 -> 13 | F28: =lang_scopes!A2 -> 1 | G28: =lang_scripts!A2 -> 1 | H28: =lang_types!A2 -> 1 | I28: Czech | J28: čeština | K28: https://raw.githubusercontent.com/dyonmulya/resources/refs/heads/main/assets/images/a2c21ad6ed68ea984ea8d1589c57f8e9.svg
A29: 28 | B29: cu | C29: chu | D29: chu | E29: =lang_families!A14 -> 13 | F29: =lang_scopes!A2 -> 1 | G29: =lang_scripts!A3 -> 2 | H29: =lang_types!A3 -> 2 | I29: Church Slavic | J29: ѩзыкъ словѣньскъ | K29: https://raw.githubusercontent.com/dyonmulya/resources/refs/heads/main/assets/images/95599abe77ed565866667dcdd78a3bb7.svg
A30: 29 | B30: cv | C30: chv | D30: chv | E30: =lang_families!A78 -> 77 | F30: =lang_scopes!A2 -> 1 | G30: =lang_scripts!A3 -> 2 | H30: =lang_types!A2 -> 1 | I30: Chuvash | J30: чӑваш чӗлхи | K30: https://raw.githubusercontent.com/dyonmulya/resources/refs/heads/main/assets/images/5367fff063561dfa0e454bbedce064b4.svg
A31: 30 | B31: cy | C31: cym | D31: cym | E31: =lang_families!A14 -> 13 | F31: =lang_scopes!A2 -> 1 | G31: =lang_scripts!A2 -> 1 | H31: =lang_types!A2 -> 1 | I31: Welsh | J31: Cymraeg | K31: https://raw.githubusercontent.com/dyonmulya/resources/refs/heads/main/assets/images/22c789d018c6280edd7798f83ec978b1.svg
A32: 31 | B32: da | C32: dan | D32: dan | E32: =lang_families!A14 -> 13 | F32: =lang_scopes!A2 -> 1 | G32: =lang_scripts!A2 -> 1 | H32: =lang_types!A2 -> 1 | I32: Danish | J32: dansk | K32: https://raw.githubusercontent.com/dyonmulya/resources/refs/heads/main/assets/images/de46addfc07857ceb3d2eae6567fadd2.svg
A33: 32 | B33: de | C33: deu | D33: deu | E33: =lang_families!A14 -> 13 | F33: =lang_scopes!A2 -> 1 | G33: =lang_scripts!A2 -> 1 | H33: =lang_types!A2 -> 1 | I33: German | J33: Deutsch | K33: https://raw.githubusercontent.com/dyonmulya/resources/refs/heads/main/assets/images/2663ee4a5910cb5eb2aa0ba8436e5dd6.svg
A34: 33 | B34: dv | C34: div | D34: div | E34: =lang_families!A14 -> 13 | F34: =lang_scopes!A2 -> 1 | G34: =lang_scripts!A9 -> 8 | H34: =lang_types!A2 -> 1 | I34: Divehi | J34: ދިވެހި | K34: https://raw.githubusercontent.com/dyonmulya/resources/refs/heads/main/assets/images/34b6f72882c3c80ced3c9f85289e6f3f.svg
A35: 34 | B35: dz | C35: dzo | D35: dzo | E35: =lang_families!A23 -> 22 | F35: =lang_scopes!A2 -> 1 | G35: =lang_scripts!A7 -> 6 | H35: =lang_types!A2 -> 1 | I35: Dzongkha | J35: རྫོང་ཁ | K35: https://raw.githubusercontent.com/dyonmulya/resources/refs/heads/main/assets/images/19b9f8fc0362e684410723c0439bb602.svg
A36: 35 | B36: ee | C36: ewe | D36: ewe | E36: =lang_families!A19 -> 18 | F36: =lang_scopes!A2 -> 1 | G36: =lang_scripts!A2 -> 1 | H36: =lang_types!A2 -> 1 | I36: Ewe | J36: Eʋegbe | K36: https://raw.githubusercontent.com/dyonmulya/resources/refs/heads/main/assets/images/3f820167903e3e00613a705d9a537932.svg
A37: 36 | B37: el | C37: ell | D37: ell | E37: =lang_families!A14 -> 13 | F37: =lang_scopes!A2 -> 1 | G37: =lang_scripts!A10 -> 9 | H37: =lang_types!A2 -> 1 | I37: Greek | J37: ελληνικά | K37: https://raw.githubusercontent.com/dyonmulya/resources/refs/heads/main/assets/images/449eaa2e6dd8539163ddb8ffcb7ca412.svg
A38: 37 | B38: en | C38: eng | D38: eng | E38: =lang_families!A14 -> 13 | F38: =lang_scopes!A2 -> 1 | G38: =lang_scripts!A2 -> 1 | H38: =lang_types!A2 -> 1 | I38: English | J38: English | K38: https://raw.githubusercontent.com/dyonmulya/resources/refs/heads/main/assets/images/df68b23c307f6e95b7fadbd309def5bd.svg
A39: 38 | B39: eo | C39: epo | D39: epo | E39: =lang_families!A29 -> 28 | F39: =lang_scopes!A2 -> 1 | G39: =lang_scripts!A2 -> 1 | H39: =lang_types!A4 -> 3 | I39: Esperanto | J39: Esperanto | K39: https://raw.githubusercontent.com/dyonmulya/resources/refs/heads/main/assets/images/729b0dd25bdbf98358a63a3a3a7dd7cd.svg
A40: 39 | B40: es | C40: spa | D40: spa | E40: =lang_families!A14 -> 13 | F40: =lang_scopes!A2 -> 1 | G40: =lang_scripts!A2 -> 1 | H40: =lang_types!A2 -> 1 | I40: Spanish | J40: español | K40: https://raw.githubusercontent.com/dyonmulya/resources/refs/heads/main/assets/images/1ce6fa7fde115d5a77b5d0313e5a3fd8.svg
...

Sheet locales
A1: id | B1: code | C1: aname | D1: uname | E1: language_id | F1: flag
A2: 1 | B2: aa | C2: Afar | D2: Afaraf | E2: =languages!A2 -> 1
A3: 2 | B3: ab | C3: Abkhaz | D3: Аԥсуа бызшәа | E3: =languages!A3 -> 2
A4: 3 | B4: ae | C4: Avestan | D4: avesta | E4: =languages!A4 -> 3
A5: 4 | B5: af | C5: Afrikaans | D5: Afrikaans | E5: =languages!A5 -> 4
A6: 5 | B6: af-NA | C6: Afrikaans (Namibia) | D6: Afrikaans (Namibië) | E6: =languages!A5 -> 4
A7: 6 | B7: af-ZA | C7: Afrikaans (South Africa) | D7: Afrikaans (Suid-Afrika) | E7: =languages!A5 -> 4
A8: 7 | B8: ak | C8: Akan | D8: Akan | E8: =languages!A6 -> 5
A9: 8 | B9: ak-GH | C9: Akan (Ghana) | D9: Akan (Gaana) | E9: =languages!A6 -> 5
A10: 9 | B10: am | C10: Amharic | D10: አማርኛ | E10: =languages!A7 -> 6
A11: 10 | B11: am-ET | C11: Amharic (Ethiopia) | D11: አማርኛ (ኢትዮጵያ) | E11: =languages!A7 -> 6
A12: 11 | B12: an | C12: Aragonese | D12: aragons | E12: =languages!A8 -> 7
A13: 12 | B13: ar | C13: Arabic | D13: العربية | E13: =languages!A9 -> 8
A14: 13 | B14: ar-AE | C14: Arabic (United Arab Emirates) | D14: العربية (الإمارات العربية المتحدة) | E14: =languages!A9 -> 8
A15: 14 | B15: ar-BH | C15: Arabic (Bahrain) | D15: العربية (البحرين) | E15: =languages!A9 -> 8
A16: 15 | B16: ar-DZ | C16: Arabic (Algeria) | D16: العربية (الجزائر) | E16: =languages!A9 -> 8
A17: 16 | B17: ar-EG | C17: Arabic (Egypt) | D17: العربية (مصر) | E17: =languages!A9 -> 8
A18: 17 | B18: ar-IQ | C18: Arabic (Iraq) | D18: العربية (العراق) | E18: =languages!A9 -> 8
A19: 18 | B19: ar-JO | C19: Arabic (Jordan) | D19: العربية (الأردن) | E19: =languages!A9 -> 8
A20: 19 | B20: ar-KW | C20: Arabic (Kuwait) | D20: العربية (الكويت) | E20: =languages!A9 -> 8
A21: 20 | B21: ar-LB | C21: Arabic (Lebanon) | D21: العربية (لبنان) | E21: =languages!A9 -> 8
A22: 21 | B22: ar-LY | C22: Arabic (Libya) | D22: العربية (ليبيا) | E22: =languages!A9 -> 8
A23: 22 | B23: ar-MA | C23: Arabic (Morocco) | D23: العربية (المغرب) | E23: =languages!A9 -> 8
A24: 23 | B24: ar-OM | C24: Arabic (Oman) | D24: العربية (عُمان) | E24: =languages!A9 -> 8
A25: 24 | B25: ar-QA | C25: Arabic (Qatar) | D25: العربية (قطر) | E25: =languages!A9 -> 8
A26: 25 | B26: ar-SA | C26: Arabic (Saudi Arabia) | D26: العربية (المملكة العربية السعودية) | E26: =languages!A9 -> 8
A27: 26 | B27: ar-SD | C27: Arabic (Sudan) | D27: العربية (السودان) | E27: =languages!A9 -> 8
A28: 27 | B28: ar-SY | C28: Arabic (Syria) | D28: العربية (سوريا) | E28: =languages!A9 -> 8
A29: 28 | B29: ar-TN | C29: Arabic (Tunisia) | D29: العربية (تونس) | E29: =languages!A9 -> 8
A30: 29 | B30: ar-YE | C30: Arabic (Yemen) | D30: العربية (اليمن) | E30: =languages!A9 -> 8
A31: 30 | B31: as | C31: Assamese | D31: অসমীয়া | E31: =languages!A10 -> 9
A32: 31 | B32: as-IN | C32: Assamese (India) | D32: অসমীয়া (ভাৰত) | E32: =languages!A10 -> 9
A33: 32 | B33: av | C33: Avaric | D33: авар мацӀ | E33: =languages!A11 -> 10
A34: 33 | B34: ay | C34: Aymara | D34: aymar aru | E34: =languages!A12 -> 11
A35: 34 | B35: az | C35: Azerbaijani | D35: azərbaycanca | E35: =languages!A13 -> 12
A36: 35 | B36: ba | C36: Bashkir | D36: башҡорт теле | E36: =languages!A14 -> 13
A37: 36 | B37: be | C37: Belarusian | D37: беларуская | E37: =languages!A15 -> 14
A38: 37 | B38: be-BY | C38: Belarusian (Belarus) | D38: беларуская (Беларусь) | E38: =languages!A15 -> 14
A39: 38 | B39: bg | C39: Bulgarian | D39: български | E39: =languages!A16 -> 15
A40: 39 | B40: bg-BG | C40: Bulgarian (Bulgaria) | D40: български (България) | E40: =languages!A16 -> 15
...
